[2025-10-24T09:36:53.282+0000] {task_context_logger.py:104} ERROR - Executor reports task instance <TaskInstance: test_email_functionality.test_failure_task manual__2025-10-24T09:36:18.489903+00:00 [queued]> finished (failed) although the task says it's queued. (Info: None) Was the task killed externally?
